Future exception was never retrieved
future: <Future finished exception=TimeoutError('Timeout')>
asyncio.exceptions.TimeoutError: Timeout

real	15m34.070s
user	0m0.007s
sys	0m0.019s
