/home/portal/anaconda3/envs/myenv/lib/python3.10/site-packages/distributed/node.py:182: UserWarning: Port 8787 is already in use.
Perhaps you already have a cluster running?
Hosting the HTTP server on port 46781 instead
  warnings.warn(
2025-09-23 18:22:55,498 - distributed.worker - WARNING - Compute Failed
Key:       compute_and_save_daily_mean-ed4cac91-c72a-48c4-b41b-9d1517188006
Function:  execute_task
args:      ((<function compute_and_save_daily_mean at 0x7f078b5dbc70>, '/work_big/users/clima/portal/CRCM5-LE/psl/kbg/2089/psl_EUR-11_CCCma-CanESM2_rcp85_r1-r7i1p1_OURANOS-CRCM5_kbg_3h_208905.nc', '/work_big/users/clima/portal/CRCM5-LE/psl/kbg/2089/psl_EUR-11_CCCma-CanESM2_rcp85_r1-r7i1p1_OURANOS-CRCM5_kbg_daily_208905.nc', 'psl', (<class 'dict'>, [['psl', (<class 'dict'>, [['zlib', 'True'], ['complevel', 5], ['dtype', 'float32']])]])))
kwargs:    {}
Exception: "FileNotFoundError(2, 'No such file or directory')"

2025-09-23 18:22:55,498 - distributed.worker - WARNING - Compute Failed
Key:       compute_and_save_daily_mean-1e13a2db-1da8-4e6f-a062-48891672cb70
Function:  execute_task
args:      ((<function compute_and_save_daily_mean at 0x7f078b5dbc70>, '/work_big/users/clima/portal/CRCM5-LE/psl/kbg/2089/psl_EUR-11_CCCma-CanESM2_rcp85_r1-r7i1p1_OURANOS-CRCM5_kbg_3h_208904.nc', '/work_big/users/clima/portal/CRCM5-LE/psl/kbg/2089/psl_EUR-11_CCCma-CanESM2_rcp85_r1-r7i1p1_OURANOS-CRCM5_kbg_daily_208904.nc', 'psl', (<class 'dict'>, [['psl', (<class 'dict'>, [['zlib', 'True'], ['complevel', 5], ['dtype', 'float32']])]])))
kwargs:    {}
Exception: "FileNotFoundError(2, 'No such file or directory')"

2025-09-23 18:22:55,499 - distributed.worker - WARNING - Compute Failed
Key:       compute_and_save_daily_mean-501a71a5-252f-480a-9a0b-702e51cf5514
Function:  execute_task
args:      ((<function compute_and_save_daily_mean at 0x7f078b5dbc70>, '/work_big/users/clima/portal/CRCM5-LE/psl/kbg/2089/psl_EUR-11_CCCma-CanESM2_rcp85_r1-r7i1p1_OURANOS-CRCM5_kbg_3h_208912.nc', '/work_big/users/clima/portal/CRCM5-LE/psl/kbg/2089/psl_EUR-11_CCCma-CanESM2_rcp85_r1-r7i1p1_OURANOS-CRCM5_kbg_daily_208912.nc', 'psl', (<class 'dict'>, [['psl', (<class 'dict'>, [['zlib', 'True'], ['complevel', 5], ['dtype', 'float32']])]])))
kwargs:    {}
Exception: "FileNotFoundError(2, 'No such file or directory')"

2025-09-23 18:22:55,501 - distributed.worker - WARNING - Compute Failed
Key:       compute_and_save_daily_mean-cabb3b55-d65c-4af6-b341-8fee6c52de31
Function:  execute_task
args:      ((<function compute_and_save_daily_mean at 0x7f078b5dbc70>, '/work_big/users/clima/portal/CRCM5-LE/psl/kbg/2089/psl_EUR-11_CCCma-CanESM2_rcp85_r1-r7i1p1_OURANOS-CRCM5_kbg_3h_208910.nc', '/work_big/users/clima/portal/CRCM5-LE/psl/kbg/2089/psl_EUR-11_CCCma-CanESM2_rcp85_r1-r7i1p1_OURANOS-CRCM5_kbg_daily_208910.nc', 'psl', (<class 'dict'>, [['psl', (<class 'dict'>, [['zlib', 'True'], ['complevel', 5], ['dtype', 'float32']])]])))
kwargs:    {}
Exception: "FileNotFoundError(2, 'No such file or directory')"

Traceback (most recent call last):
  File "/home/portal/script/python/compute_daily-mean_dask.py", line 56, in <module>
    dask.compute(*dd)
  File "/home/portal/anaconda3/envs/myenv/lib/python3.10/site-packages/dask/base.py", line 661, in compute
    results = schedule(dsk, keys, **kwargs)
  File "/home/portal/script/python/functions_preprocessing.py", line 46, in compute_and_save_daily_mean
    ds = xr.open_dataset(file_in)
  File "/home/portal/anaconda3/envs/myenv/lib/python3.10/site-packages/xarray/backends/api.py", line 539, in open_dataset
    backend_ds = backend.open_dataset(
  File "/home/portal/anaconda3/envs/myenv/lib/python3.10/site-packages/xarray/backends/netCDF4_.py", line 572, in open_dataset
    store = NetCDF4DataStore.open(
  File "/home/portal/anaconda3/envs/myenv/lib/python3.10/site-packages/xarray/backends/netCDF4_.py", line 376, in open
    return cls(manager, group=group, mode=mode, lock=lock, autoclose=autoclose)
  File "/home/portal/anaconda3/envs/myenv/lib/python3.10/site-packages/xarray/backends/netCDF4_.py", line 323, in __init__
    self.format = self.ds.data_model
  File "/home/portal/anaconda3/envs/myenv/lib/python3.10/site-packages/xarray/backends/netCDF4_.py", line 385, in ds
    return self._acquire()
  File "/home/portal/anaconda3/envs/myenv/lib/python3.10/site-packages/xarray/backends/netCDF4_.py", line 379, in _acquire
    with self._manager.acquire_context(needs_lock) as root:
  File "/home/portal/anaconda3/envs/myenv/lib/python3.10/contextlib.py", line 135, in __enter__
    return next(self.gen)
  File "/home/portal/anaconda3/envs/myenv/lib/python3.10/site-packages/xarray/backends/file_manager.py", line 197, in acquire_context
    file, cached = self._acquire_with_cache_info(needs_lock)
  File "/home/portal/anaconda3/envs/myenv/lib/python3.10/site-packages/xarray/backends/file_manager.py", line 215, in _acquire_with_cache_info
    file = self._opener(*self._args, **kwargs)
  File "src/netCDF4/_netCDF4.pyx", line 2463, in netCDF4._netCDF4.Dataset.__init__
  File "src/netCDF4/_netCDF4.pyx", line 2026, in netCDF4._netCDF4._ensure_nc_success
FileNotFoundError: [Errno 2] No such file or directory: b'/work_big/users/clima/portal/CRCM5-LE/psl/kbg/2089/psl_EUR-11_CCCma-CanESM2_rcp85_r1-r7i1p1_OURANOS-CRCM5_kbg_3h_208905.nc'
2025-09-23 18:22:55,520 - distributed.worker.state_machine - WARNING - Async instruction for <Task cancelled name="execute('compute_and_save_daily_mean-c291db55-7b99-4fd3-ba0d-7bebee196c42')" coro=<Worker.execute() done, defined at /home/portal/anaconda3/envs/myenv/lib/python3.10/site-packages/distributed/worker_state_machine.py:3615>> ended with CancelledError
2025-09-23 18:22:55,520 - distributed.worker.state_machine - WARNING - Async instruction for <Task cancelled name="execute('compute_and_save_daily_mean-12998f16-79ab-4d1e-be66-1ec9034b5db4')" coro=<Worker.execute() done, defined at /home/portal/anaconda3/envs/myenv/lib/python3.10/site-packages/distributed/worker_state_machine.py:3615>> ended with CancelledError
2025-09-23 18:22:55,520 - distributed.worker.state_machine - WARNING - Async instruction for <Task cancelled name="execute('compute_and_save_daily_mean-e57d1a57-bce1-4831-bafb-e46f56cc6f12')" coro=<Worker.execute() done, defined at /home/portal/anaconda3/envs/myenv/lib/python3.10/site-packages/distributed/worker_state_machine.py:3615>> ended with CancelledError
2025-09-23 18:22:55,520 - distributed.worker.state_machine - WARNING - Async instruction for <Task cancelled name="execute('compute_and_save_daily_mean-4fc67e52-a5a0-45bd-a749-84ce258c04d5')" coro=<Worker.execute() done, defined at /home/portal/anaconda3/envs/myenv/lib/python3.10/site-packages/distributed/worker_state_machine.py:3615>> ended with CancelledError
2025-09-23 18:22:55,521 - distributed.worker.state_machine - WARNING - Async instruction for <Task cancelled name="execute('compute_and_save_daily_mean-d35bdc09-eecc-484d-9aeb-1e33149fce2a')" coro=<Worker.execute() done, defined at /home/portal/anaconda3/envs/myenv/lib/python3.10/site-packages/distributed/worker_state_machine.py:3615>> ended with CancelledError
2025-09-23 18:22:55,521 - distributed.worker.state_machine - WARNING - Async instruction for <Task cancelled name="execute('compute_and_save_daily_mean-3c8470e5-4c25-48c3-9991-79d90c72fe14')" coro=<Worker.execute() done, defined at /home/portal/anaconda3/envs/myenv/lib/python3.10/site-packages/distributed/worker_state_machine.py:3615>> ended with CancelledError
2025-09-23 18:22:55,521 - distributed.worker.state_machine - WARNING - Async instruction for <Task cancelled name="execute('compute_and_save_daily_mean-f823b00f-e17b-4692-86fa-624064d92889')" coro=<Worker.execute() done, defined at /home/portal/anaconda3/envs/myenv/lib/python3.10/site-packages/distributed/worker_state_machine.py:3615>> ended with CancelledError
2025-09-23 18:22:55,521 - distributed.worker.state_machine - WARNING - Async instruction for <Task cancelled name="execute('compute_and_save_daily_mean-7a1ae520-bc5d-4814-bc0d-bc52e9b1e145')" coro=<Worker.execute() done, defined at /home/portal/anaconda3/envs/myenv/lib/python3.10/site-packages/distributed/worker_state_machine.py:3615>> ended with CancelledError

real	0m2.682s
user	0m4.552s
sys	0m4.504s
