Exception ignored in: <function CachingFileManager.__del__ at 0x7f8d6f7c9630>
Traceback (most recent call last):
  File "/home/portal/anaconda3/envs/myenv/lib/python3.10/site-packages/xarray/backends/file_manager.py", line 248, in __del__
    self.close(needs_lock=False)
  File "/home/portal/anaconda3/envs/myenv/lib/python3.10/site-packages/xarray/backends/file_manager.py", line 232, in close
    file.close()
  File "src/netCDF4/_netCDF4.pyx", line 2624, in netCDF4._netCDF4.Dataset.close
  File "src/netCDF4/_netCDF4.pyx", line 2587, in netCDF4._netCDF4.Dataset._close
  File "src/netCDF4/_netCDF4.pyx", line 2028, in netCDF4._netCDF4._ensure_nc_success
RuntimeError: NetCDF: Not a valid ID

real	8m32.831s
user	5m48.079s
sys	3m6.404s
