/home/portal/anaconda3/envs/myenv/lib/python3.10/site-packages/distributed/node.py:182: UserWarning: Port 8787 is already in use.
Perhaps you already have a cluster running?
Hosting the HTTP server on port 42711 instead
  warnings.warn(
Future exception was never retrieved
future: <Future finished exception=TimeoutError('Timeout')>
asyncio.exceptions.TimeoutError: Timeout

real	6m25.575s
user	5m32.120s
sys	2m38.677s
