/home/portal/anaconda3/envs/myenv/lib/python3.10/site-packages/distributed/node.py:182: UserWarning: Port 8787 is already in use.
Perhaps you already have a cluster running?
Hosting the HTTP server on port 37567 instead
  warnings.warn(
free(): invalid pointer
2024-11-25 03:04:55,698 - distributed.nanny - WARNING - Restarting worker
Exception ignored in: <function CachingFileManager.__del__ at 0x7fce4e485630>
Traceback (most recent call last):
  File "/home/portal/anaconda3/envs/myenv/lib/python3.10/site-packages/xarray/backends/file_manager.py", line 248, in __del__
    self.close(needs_lock=False)
  File "/home/portal/anaconda3/envs/myenv/lib/python3.10/site-packages/xarray/backends/file_manager.py", line 232, in close
    file.close()
  File "src/netCDF4/_netCDF4.pyx", line 2624, in netCDF4._netCDF4.Dataset.close
  File "src/netCDF4/_netCDF4.pyx", line 2587, in netCDF4._netCDF4.Dataset._close
  File "src/netCDF4/_netCDF4.pyx", line 2028, in netCDF4._netCDF4._ensure_nc_success
RuntimeError: NetCDF: Not a valid ID

real	17m21.387s
user	9m9.163s
sys	3m19.237s
