/home/portal/anaconda3/envs/myenv/lib/python3.10/site-packages/distributed/node.py:182: UserWarning: Port 8787 is already in use.
Perhaps you already have a cluster running?
Hosting the HTTP server on port 44025 instead
  warnings.warn(
2025-09-23 18:20:25,379 - distributed.worker - WARNING - Compute Failed
Key:       compute_and_save_daily_mean-e9b5e6cb-08ed-4463-9eae-251884c32271
Function:  execute_task
args:      ((<function compute_and_save_daily_mean at 0x7ff5f172bc70>, '/work_big/users/clima/portal/CRCM5-LE/psl/kbg/2059/psl_EUR-11_CCCma-CanESM2_rcp85_r1-r7i1p1_OURANOS-CRCM5_kbg_3h_205907.nc', '/work_big/users/clima/portal/CRCM5-LE/psl/kbg/2059/psl_EUR-11_CCCma-CanESM2_rcp85_r1-r7i1p1_OURANOS-CRCM5_kbg_daily_205907.nc', 'psl', (<class 'dict'>, [['psl', (<class 'dict'>, [['zlib', 'True'], ['complevel', 5], ['dtype', 'float32']])]])))
kwargs:    {}
Exception: "FileNotFoundError(2, 'No such file or directory')"

2025-09-23 18:20:25,379 - distributed.worker - WARNING - Compute Failed
Key:       compute_and_save_daily_mean-c3dd209c-2360-4761-bbe8-f7ce0f3033a1
Function:  execute_task
args:      ((<function compute_and_save_daily_mean at 0x7ff5f172bc70>, '/work_big/users/clima/portal/CRCM5-LE/psl/kbg/2059/psl_EUR-11_CCCma-CanESM2_rcp85_r1-r7i1p1_OURANOS-CRCM5_kbg_3h_205902.nc', '/work_big/users/clima/portal/CRCM5-LE/psl/kbg/2059/psl_EUR-11_CCCma-CanESM2_rcp85_r1-r7i1p1_OURANOS-CRCM5_kbg_daily_205902.nc', 'psl', (<class 'dict'>, [['psl', (<class 'dict'>, [['zlib', 'True'], ['complevel', 5], ['dtype', 'float32']])]])))
kwargs:    {}
Exception: "FileNotFoundError(2, 'No such file or directory')"

2025-09-23 18:20:25,379 - distributed.worker - WARNING - Compute Failed
Key:       compute_and_save_daily_mean-6969127f-79f5-44b0-8043-68c17a04dd21
Function:  execute_task
args:      ((<function compute_and_save_daily_mean at 0x7ff5f172bc70>, '/work_big/users/clima/portal/CRCM5-LE/psl/kbg/2059/psl_EUR-11_CCCma-CanESM2_rcp85_r1-r7i1p1_OURANOS-CRCM5_kbg_3h_205910.nc', '/work_big/users/clima/portal/CRCM5-LE/psl/kbg/2059/psl_EUR-11_CCCma-CanESM2_rcp85_r1-r7i1p1_OURANOS-CRCM5_kbg_daily_205910.nc', 'psl', (<class 'dict'>, [['psl', (<class 'dict'>, [['zlib', 'True'], ['complevel', 5], ['dtype', 'float32']])]])))
kwargs:    {}
Exception: "FileNotFoundError(2, 'No such file or directory')"

2025-09-23 18:20:25,383 - distributed.worker - WARNING - Compute Failed
Key:       compute_and_save_daily_mean-1ab31cff-a68e-480c-a93b-1cd3ec552fe8
Function:  execute_task
args:      ((<function compute_and_save_daily_mean at 0x7ff5f172bc70>, '/work_big/users/clima/portal/CRCM5-LE/psl/kbg/2059/psl_EUR-11_CCCma-CanESM2_rcp85_r1-r7i1p1_OURANOS-CRCM5_kbg_3h_205908.nc', '/work_big/users/clima/portal/CRCM5-LE/psl/kbg/2059/psl_EUR-11_CCCma-CanESM2_rcp85_r1-r7i1p1_OURANOS-CRCM5_kbg_daily_205908.nc', 'psl', (<class 'dict'>, [['psl', (<class 'dict'>, [['zlib', 'True'], ['complevel', 5], ['dtype', 'float32']])]])))
kwargs:    {}
Exception: "FileNotFoundError(2, 'No such file or directory')"

Traceback (most recent call last):
  File "/home/portal/script/python/compute_daily-mean_dask.py", line 56, in <module>
    dask.compute(*dd)
  File "/home/portal/anaconda3/envs/myenv/lib/python3.10/site-packages/dask/base.py", line 661, in compute
    results = schedule(dsk, keys, **kwargs)
  File "/home/portal/script/python/functions_preprocessing.py", line 46, in compute_and_save_daily_mean
    ds = xr.open_dataset(file_in)
  File "/home/portal/anaconda3/envs/myenv/lib/python3.10/site-packages/xarray/backends/api.py", line 539, in open_dataset
    backend_ds = backend.open_dataset(
  File "/home/portal/anaconda3/envs/myenv/lib/python3.10/site-packages/xarray/backends/netCDF4_.py", line 572, in open_dataset
    store = NetCDF4DataStore.open(
  File "/home/portal/anaconda3/envs/myenv/lib/python3.10/site-packages/xarray/backends/netCDF4_.py", line 376, in open
    return cls(manager, group=group, mode=mode, lock=lock, autoclose=autoclose)
  File "/home/portal/anaconda3/envs/myenv/lib/python3.10/site-packages/xarray/backends/netCDF4_.py", line 323, in __init__
    self.format = self.ds.data_model
  File "/home/portal/anaconda3/envs/myenv/lib/python3.10/site-packages/xarray/backends/netCDF4_.py", line 385, in ds
    return self._acquire()
  File "/home/portal/anaconda3/envs/myenv/lib/python3.10/site-packages/xarray/backends/netCDF4_.py", line 379, in _acquire
    with self._manager.acquire_context(needs_lock) as root:
  File "/home/portal/anaconda3/envs/myenv/lib/python3.10/contextlib.py", line 135, in __enter__
    return next(self.gen)
  File "/home/portal/anaconda3/envs/myenv/lib/python3.10/site-packages/xarray/backends/file_manager.py", line 197, in acquire_context
    file, cached = self._acquire_with_cache_info(needs_lock)
  File "/home/portal/anaconda3/envs/myenv/lib/python3.10/site-packages/xarray/backends/file_manager.py", line 215, in _acquire_with_cache_info
    file = self._opener(*self._args, **kwargs)
  File "src/netCDF4/_netCDF4.pyx", line 2463, in netCDF4._netCDF4.Dataset.__init__
  File "src/netCDF4/_netCDF4.pyx", line 2026, in netCDF4._netCDF4._ensure_nc_success
FileNotFoundError: [Errno 2] No such file or directory: b'/work_big/users/clima/portal/CRCM5-LE/psl/kbg/2059/psl_EUR-11_CCCma-CanESM2_rcp85_r1-r7i1p1_OURANOS-CRCM5_kbg_3h_205907.nc'
2025-09-23 18:20:25,404 - distributed.worker - WARNING - Compute Failed
Key:       compute_and_save_daily_mean-c542c753-8837-4aae-951e-a7737fe77b1c
Function:  execute_task
args:      ((<function compute_and_save_daily_mean at 0x7f408a773c70>, '/work_big/users/clima/portal/CRCM5-LE/psl/kbg/2059/psl_EUR-11_CCCma-CanESM2_rcp85_r1-r7i1p1_OURANOS-CRCM5_kbg_3h_205906.nc', '/work_big/users/clima/portal/CRCM5-LE/psl/kbg/2059/psl_EUR-11_CCCma-CanESM2_rcp85_r1-r7i1p1_OURANOS-CRCM5_kbg_daily_205906.nc', 'psl', (<class 'dict'>, [['psl', (<class 'dict'>, [['zlib', 'True'], ['complevel', 5], ['dtype', 'float32']])]])))
kwargs:    {}
Exception: "FileNotFoundError(2, 'No such file or directory')"

2025-09-23 18:20:25,405 - distributed.worker - WARNING - Compute Failed
Key:       compute_and_save_daily_mean-49bde181-e297-47b3-913b-62171dcd315c
Function:  execute_task
args:      ((<function compute_and_save_daily_mean at 0x7f408a773c70>, '/work_big/users/clima/portal/CRCM5-LE/psl/kbg/2059/psl_EUR-11_CCCma-CanESM2_rcp85_r1-r7i1p1_OURANOS-CRCM5_kbg_3h_205904.nc', '/work_big/users/clima/portal/CRCM5-LE/psl/kbg/2059/psl_EUR-11_CCCma-CanESM2_rcp85_r1-r7i1p1_OURANOS-CRCM5_kbg_daily_205904.nc', 'psl', (<class 'dict'>, [['psl', (<class 'dict'>, [['zlib', 'True'], ['complevel', 5], ['dtype', 'float32']])]])))
kwargs:    {}
Exception: "FileNotFoundError(2, 'No such file or directory')"

2025-09-23 18:20:25,405 - distributed.worker - WARNING - Compute Failed
Key:       compute_and_save_daily_mean-74531a86-9191-4c63-b48b-759aab5400f6
Function:  execute_task
args:      ((<function compute_and_save_daily_mean at 0x7f408a773c70>, '/work_big/users/clima/portal/CRCM5-LE/psl/kbg/2059/psl_EUR-11_CCCma-CanESM2_rcp85_r1-r7i1p1_OURANOS-CRCM5_kbg_3h_205903.nc', '/work_big/users/clima/portal/CRCM5-LE/psl/kbg/2059/psl_EUR-11_CCCma-CanESM2_rcp85_r1-r7i1p1_OURANOS-CRCM5_kbg_daily_205903.nc', 'psl', (<class 'dict'>, [['psl', (<class 'dict'>, [['zlib', 'True'], ['complevel', 5], ['dtype', 'float32']])]])))
kwargs:    {}
Exception: "FileNotFoundError(2, 'No such file or directory')"

2025-09-23 18:20:25,408 - distributed.worker - WARNING - Compute Failed
Key:       compute_and_save_daily_mean-013c5bbc-7056-448f-9223-6851546f47f5
Function:  execute_task
args:      ((<function compute_and_save_daily_mean at 0x7f408a773c70>, '/work_big/users/clima/portal/CRCM5-LE/psl/kbg/2059/psl_EUR-11_CCCma-CanESM2_rcp85_r1-r7i1p1_OURANOS-CRCM5_kbg_3h_205905.nc', '/work_big/users/clima/portal/CRCM5-LE/psl/kbg/2059/psl_EUR-11_CCCma-CanESM2_rcp85_r1-r7i1p1_OURANOS-CRCM5_kbg_daily_205905.nc', 'psl', (<class 'dict'>, [['psl', (<class 'dict'>, [['zlib', 'True'], ['complevel', 5], ['dtype', 'float32']])]])))
kwargs:    {}
Exception: "FileNotFoundError(2, 'No such file or directory')"

2025-09-23 18:20:25,410 - distributed.worker.state_machine - WARNING - Async instruction for <Task cancelled name="execute('compute_and_save_daily_mean-a4dd4eda-f1df-4ff1-94da-68825a34609d')" coro=<Worker.execute() done, defined at /home/portal/anaconda3/envs/myenv/lib/python3.10/site-packages/distributed/worker_state_machine.py:3615>> ended with CancelledError
2025-09-23 18:20:25,410 - distributed.worker.state_machine - WARNING - Async instruction for <Task cancelled name="execute('compute_and_save_daily_mean-13db3879-ee88-42c8-a4b2-2016a00e0610')" coro=<Worker.execute() done, defined at /home/portal/anaconda3/envs/myenv/lib/python3.10/site-packages/distributed/worker_state_machine.py:3615>> ended with CancelledError
2025-09-23 18:20:25,410 - distributed.worker.state_machine - WARNING - Async instruction for <Task cancelled name="execute('compute_and_save_daily_mean-e15afa2b-5c49-44e0-bced-eaf25de73128')" coro=<Worker.execute() done, defined at /home/portal/anaconda3/envs/myenv/lib/python3.10/site-packages/distributed/worker_state_machine.py:3615>> ended with CancelledError
2025-09-23 18:20:25,410 - distributed.worker.state_machine - WARNING - Async instruction for <Task cancelled name="execute('compute_and_save_daily_mean-5f9d429d-57bc-451b-a9e9-dcdd02f44b1d')" coro=<Worker.execute() done, defined at /home/portal/anaconda3/envs/myenv/lib/python3.10/site-packages/distributed/worker_state_machine.py:3615>> ended with CancelledError

real	0m2.567s
user	0m5.721s
sys	0m13.816s
