/home/portal/anaconda3/envs/myenv/lib/python3.10/site-packages/distributed/node.py:182: UserWarning: Port 8787 is already in use.
Perhaps you already have a cluster running?
Hosting the HTTP server on port 33351 instead
  warnings.warn(
2025-09-23 18:23:28,578 - distributed.worker - WARNING - Compute Failed
Key:       compute_and_save_daily_mean-61ace9cf-b61f-4678-88c7-57bb68f3f433
Function:  execute_task
args:      ((<function compute_and_save_daily_mean at 0x7f31c17fbc70>, '/work_big/users/clima/portal/CRCM5-LE/psl/kbg/2098/psl_EUR-11_CCCma-CanESM2_rcp85_r1-r7i1p1_OURANOS-CRCM5_kbg_3h_209809.nc', '/work_big/users/clima/portal/CRCM5-LE/psl/kbg/2098/psl_EUR-11_CCCma-CanESM2_rcp85_r1-r7i1p1_OURANOS-CRCM5_kbg_daily_209809.nc', 'psl', (<class 'dict'>, [['psl', (<class 'dict'>, [['zlib', 'True'], ['complevel', 5], ['dtype', 'float32']])]])))
kwargs:    {}
Exception: "FileNotFoundError(2, 'No such file or directory')"

2025-09-23 18:23:28,578 - distributed.worker - WARNING - Compute Failed
Key:       compute_and_save_daily_mean-a217ab66-7c6b-4f4c-ba78-fd6ee460e566
Function:  execute_task
args:      ((<function compute_and_save_daily_mean at 0x7f31c17fbc70>, '/work_big/users/clima/portal/CRCM5-LE/psl/kbg/2098/psl_EUR-11_CCCma-CanESM2_rcp85_r1-r7i1p1_OURANOS-CRCM5_kbg_3h_209808.nc', '/work_big/users/clima/portal/CRCM5-LE/psl/kbg/2098/psl_EUR-11_CCCma-CanESM2_rcp85_r1-r7i1p1_OURANOS-CRCM5_kbg_daily_209808.nc', 'psl', (<class 'dict'>, [['psl', (<class 'dict'>, [['zlib', 'True'], ['complevel', 5], ['dtype', 'float32']])]])))
kwargs:    {}
Exception: "FileNotFoundError(2, 'No such file or directory')"

2025-09-23 18:23:28,580 - distributed.worker - WARNING - Compute Failed
Key:       compute_and_save_daily_mean-ceb43431-7cb1-48c3-8e58-48b3f10e3b91
Function:  execute_task
args:      ((<function compute_and_save_daily_mean at 0x7f31c17fbc70>, '/work_big/users/clima/portal/CRCM5-LE/psl/kbg/2098/psl_EUR-11_CCCma-CanESM2_rcp85_r1-r7i1p1_OURANOS-CRCM5_kbg_3h_209810.nc', '/work_big/users/clima/portal/CRCM5-LE/psl/kbg/2098/psl_EUR-11_CCCma-CanESM2_rcp85_r1-r7i1p1_OURANOS-CRCM5_kbg_daily_209810.nc', 'psl', (<class 'dict'>, [['psl', (<class 'dict'>, [['zlib', 'True'], ['complevel', 5], ['dtype', 'float32']])]])))
kwargs:    {}
Exception: "FileNotFoundError(2, 'No such file or directory')"

2025-09-23 18:23:28,580 - distributed.worker - WARNING - Compute Failed
Key:       compute_and_save_daily_mean-03f83629-a283-4470-a5d3-0b2a9e0bbfdf
Function:  execute_task
args:      ((<function compute_and_save_daily_mean at 0x7f31c17fbc70>, '/work_big/users/clima/portal/CRCM5-LE/psl/kbg/2098/psl_EUR-11_CCCma-CanESM2_rcp85_r1-r7i1p1_OURANOS-CRCM5_kbg_3h_209804.nc', '/work_big/users/clima/portal/CRCM5-LE/psl/kbg/2098/psl_EUR-11_CCCma-CanESM2_rcp85_r1-r7i1p1_OURANOS-CRCM5_kbg_daily_209804.nc', 'psl', (<class 'dict'>, [['psl', (<class 'dict'>, [['zlib', 'True'], ['complevel', 5], ['dtype', 'float32']])]])))
kwargs:    {}
Exception: "FileNotFoundError(2, 'No such file or directory')"

Traceback (most recent call last):
  File "/home/portal/script/python/compute_daily-mean_dask.py", line 56, in <module>
    dask.compute(*dd)
  File "/home/portal/anaconda3/envs/myenv/lib/python3.10/site-packages/dask/base.py", line 661, in compute
    results = schedule(dsk, keys, **kwargs)
  File "/home/portal/script/python/functions_preprocessing.py", line 46, in compute_and_save_daily_mean
    ds = xr.open_dataset(file_in)
  File "/home/portal/anaconda3/envs/myenv/lib/python3.10/site-packages/xarray/backends/api.py", line 539, in open_dataset
    backend_ds = backend.open_dataset(
  File "/home/portal/anaconda3/envs/myenv/lib/python3.10/site-packages/xarray/backends/netCDF4_.py", line 572, in open_dataset
    store = NetCDF4DataStore.open(
  File "/home/portal/anaconda3/envs/myenv/lib/python3.10/site-packages/xarray/backends/netCDF4_.py", line 376, in open
    return cls(manager, group=group, mode=mode, lock=lock, autoclose=autoclose)
  File "/home/portal/anaconda3/envs/myenv/lib/python3.10/site-packages/xarray/backends/netCDF4_.py", line 323, in __init__
    self.format = self.ds.data_model
  File "/home/portal/anaconda3/envs/myenv/lib/python3.10/site-packages/xarray/backends/netCDF4_.py", line 385, in ds
    return self._acquire()
  File "/home/portal/anaconda3/envs/myenv/lib/python3.10/site-packages/xarray/backends/netCDF4_.py", line 379, in _acquire
    with self._manager.acquire_context(needs_lock) as root:
  File "/home/portal/anaconda3/envs/myenv/lib/python3.10/contextlib.py", line 135, in __enter__
    return next(self.gen)
  File "/home/portal/anaconda3/envs/myenv/lib/python3.10/site-packages/xarray/backends/file_manager.py", line 197, in acquire_context
    file, cached = self._acquire_with_cache_info(needs_lock)
  File "/home/portal/anaconda3/envs/myenv/lib/python3.10/site-packages/xarray/backends/file_manager.py", line 215, in _acquire_with_cache_info
    file = self._opener(*self._args, **kwargs)
  File "src/netCDF4/_netCDF4.pyx", line 2463, in netCDF4._netCDF4.Dataset.__init__
  File "src/netCDF4/_netCDF4.pyx", line 2026, in netCDF4._netCDF4._ensure_nc_success
FileNotFoundError: [Errno 2] No such file or directory: b'/work_big/users/clima/portal/CRCM5-LE/psl/kbg/2098/psl_EUR-11_CCCma-CanESM2_rcp85_r1-r7i1p1_OURANOS-CRCM5_kbg_3h_209809.nc'
2025-09-23 18:23:28,613 - distributed.worker.state_machine - WARNING - Async instruction for <Task cancelled name="execute('compute_and_save_daily_mean-b855f8b5-de70-4826-812a-0f1127c20d46')" coro=<Worker.execute() done, defined at /home/portal/anaconda3/envs/myenv/lib/python3.10/site-packages/distributed/worker_state_machine.py:3615>> ended with CancelledError
2025-09-23 18:23:28,613 - distributed.worker.state_machine - WARNING - Async instruction for <Task cancelled name="execute('compute_and_save_daily_mean-38a80fb3-9477-440c-9822-156be41ce5ad')" coro=<Worker.execute() done, defined at /home/portal/anaconda3/envs/myenv/lib/python3.10/site-packages/distributed/worker_state_machine.py:3615>> ended with CancelledError
2025-09-23 18:23:28,614 - distributed.worker.state_machine - WARNING - Async instruction for <Task cancelled name="execute('compute_and_save_daily_mean-f9608d63-7183-43fe-892e-ba933daa8d46')" coro=<Worker.execute() done, defined at /home/portal/anaconda3/envs/myenv/lib/python3.10/site-packages/distributed/worker_state_machine.py:3615>> ended with CancelledError
2025-09-23 18:23:28,614 - distributed.worker.state_machine - WARNING - Async instruction for <Task cancelled name="execute('compute_and_save_daily_mean-71f37487-8ba2-4526-969e-0c2f3b9b859d')" coro=<Worker.execute() done, defined at /home/portal/anaconda3/envs/myenv/lib/python3.10/site-packages/distributed/worker_state_machine.py:3615>> ended with CancelledError
2025-09-23 18:23:28,614 - distributed.worker.state_machine - WARNING - Async instruction for <Task cancelled name="execute('compute_and_save_daily_mean-a7baf13b-b2e9-44b6-bfd2-bef5d5809f1c')" coro=<Worker.execute() done, defined at /home/portal/anaconda3/envs/myenv/lib/python3.10/site-packages/distributed/worker_state_machine.py:3615>> ended with CancelledError
2025-09-23 18:23:28,614 - distributed.worker.state_machine - WARNING - Async instruction for <Task cancelled name="execute('compute_and_save_daily_mean-105f09cc-3df7-48df-b449-40809fbd6e20')" coro=<Worker.execute() done, defined at /home/portal/anaconda3/envs/myenv/lib/python3.10/site-packages/distributed/worker_state_machine.py:3615>> ended with CancelledError
2025-09-23 18:23:28,614 - distributed.worker.state_machine - WARNING - Async instruction for <Task cancelled name="execute('compute_and_save_daily_mean-ddeb8f55-6af3-407b-9620-4c3aa6f5da61')" coro=<Worker.execute() done, defined at /home/portal/anaconda3/envs/myenv/lib/python3.10/site-packages/distributed/worker_state_machine.py:3615>> ended with CancelledError
2025-09-23 18:23:28,614 - distributed.worker.state_machine - WARNING - Async instruction for <Task cancelled name="execute('compute_and_save_daily_mean-6a383223-9490-4b81-a3ff-c37e354e367f')" coro=<Worker.execute() done, defined at /home/portal/anaconda3/envs/myenv/lib/python3.10/site-packages/distributed/worker_state_machine.py:3615>> ended with CancelledError

real	0m2.802s
user	0m6.237s
sys	0m14.484s
