/home/portal/anaconda3/envs/myenv/lib/python3.10/site-packages/distributed/node.py:182: UserWarning: Port 8787 is already in use.
Perhaps you already have a cluster running?
Hosting the HTTP server on port 41323 instead
  warnings.warn(
2025-09-23 18:20:55,818 - distributed.worker - WARNING - Compute Failed
Key:       compute_and_save_daily_mean-186d3035-047d-4e0a-82b7-37f501a42d9e
Function:  execute_task
args:      ((<function compute_and_save_daily_mean at 0x7f35f022bc70>, '/work_big/users/clima/portal/CRCM5-LE/psl/kbg/2066/psl_EUR-11_CCCma-CanESM2_rcp85_r1-r7i1p1_OURANOS-CRCM5_kbg_3h_206607.nc', '/work_big/users/clima/portal/CRCM5-LE/psl/kbg/2066/psl_EUR-11_CCCma-CanESM2_rcp85_r1-r7i1p1_OURANOS-CRCM5_kbg_daily_206607.nc', 'psl', (<class 'dict'>, [['psl', (<class 'dict'>, [['zlib', 'True'], ['complevel', 5], ['dtype', 'float32']])]])))
kwargs:    {}
Exception: "FileNotFoundError(2, 'No such file or directory')"

2025-09-23 18:20:55,819 - distributed.worker - WARNING - Compute Failed
Key:       compute_and_save_daily_mean-de677ef0-5d07-463b-951d-550be74873e5
Function:  execute_task
args:      ((<function compute_and_save_daily_mean at 0x7f35f022bc70>, '/work_big/users/clima/portal/CRCM5-LE/psl/kbg/2066/psl_EUR-11_CCCma-CanESM2_rcp85_r1-r7i1p1_OURANOS-CRCM5_kbg_3h_206601.nc', '/work_big/users/clima/portal/CRCM5-LE/psl/kbg/2066/psl_EUR-11_CCCma-CanESM2_rcp85_r1-r7i1p1_OURANOS-CRCM5_kbg_daily_206601.nc', 'psl', (<class 'dict'>, [['psl', (<class 'dict'>, [['zlib', 'True'], ['complevel', 5], ['dtype', 'float32']])]])))
kwargs:    {}
Exception: "FileNotFoundError(2, 'No such file or directory')"

2025-09-23 18:20:55,819 - distributed.worker - WARNING - Compute Failed
Key:       compute_and_save_daily_mean-b12af7e4-c5fc-4890-b2bb-35f28e150e9b
Function:  execute_task
args:      ((<function compute_and_save_daily_mean at 0x7f35f022bc70>, '/work_big/users/clima/portal/CRCM5-LE/psl/kbg/2066/psl_EUR-11_CCCma-CanESM2_rcp85_r1-r7i1p1_OURANOS-CRCM5_kbg_3h_206610.nc', '/work_big/users/clima/portal/CRCM5-LE/psl/kbg/2066/psl_EUR-11_CCCma-CanESM2_rcp85_r1-r7i1p1_OURANOS-CRCM5_kbg_daily_206610.nc', 'psl', (<class 'dict'>, [['psl', (<class 'dict'>, [['zlib', 'True'], ['complevel', 5], ['dtype', 'float32']])]])))
kwargs:    {}
Exception: "FileNotFoundError(2, 'No such file or directory')"

2025-09-23 18:20:55,821 - distributed.worker - WARNING - Compute Failed
Key:       compute_and_save_daily_mean-3cc3ca68-26b2-4ec5-9d86-8d4cb2ed0f24
Function:  execute_task
args:      ((<function compute_and_save_daily_mean at 0x7f35f022bc70>, '/work_big/users/clima/portal/CRCM5-LE/psl/kbg/2066/psl_EUR-11_CCCma-CanESM2_rcp85_r1-r7i1p1_OURANOS-CRCM5_kbg_3h_206604.nc', '/work_big/users/clima/portal/CRCM5-LE/psl/kbg/2066/psl_EUR-11_CCCma-CanESM2_rcp85_r1-r7i1p1_OURANOS-CRCM5_kbg_daily_206604.nc', 'psl', (<class 'dict'>, [['psl', (<class 'dict'>, [['zlib', 'True'], ['complevel', 5], ['dtype', 'float32']])]])))
kwargs:    {}
Exception: "FileNotFoundError(2, 'No such file or directory')"

Traceback (most recent call last):
  File "/home/portal/script/python/compute_daily-mean_dask.py", line 56, in <module>
    dask.compute(*dd)
  File "/home/portal/anaconda3/envs/myenv/lib/python3.10/site-packages/dask/base.py", line 661, in compute
    results = schedule(dsk, keys, **kwargs)
  File "/home/portal/script/python/functions_preprocessing.py", line 46, in compute_and_save_daily_mean
    ds = xr.open_dataset(file_in)
  File "/home/portal/anaconda3/envs/myenv/lib/python3.10/site-packages/xarray/backends/api.py", line 539, in open_dataset
    backend_ds = backend.open_dataset(
  File "/home/portal/anaconda3/envs/myenv/lib/python3.10/site-packages/xarray/backends/netCDF4_.py", line 572, in open_dataset
    store = NetCDF4DataStore.open(
  File "/home/portal/anaconda3/envs/myenv/lib/python3.10/site-packages/xarray/backends/netCDF4_.py", line 376, in open
    return cls(manager, group=group, mode=mode, lock=lock, autoclose=autoclose)
  File "/home/portal/anaconda3/envs/myenv/lib/python3.10/site-packages/xarray/backends/netCDF4_.py", line 323, in __init__
    self.format = self.ds.data_model
  File "/home/portal/anaconda3/envs/myenv/lib/python3.10/site-packages/xarray/backends/netCDF4_.py", line 385, in ds
    return self._acquire()
  File "/home/portal/anaconda3/envs/myenv/lib/python3.10/site-packages/xarray/backends/netCDF4_.py", line 379, in _acquire
    with self._manager.acquire_context(needs_lock) as root:
  File "/home/portal/anaconda3/envs/myenv/lib/python3.10/contextlib.py", line 135, in __enter__
    return next(self.gen)
  File "/home/portal/anaconda3/envs/myenv/lib/python3.10/site-packages/xarray/backends/file_manager.py", line 197, in acquire_context
    file, cached = self._acquire_with_cache_info(needs_lock)
  File "/home/portal/anaconda3/envs/myenv/lib/python3.10/site-packages/xarray/backends/file_manager.py", line 215, in _acquire_with_cache_info
    file = self._opener(*self._args, **kwargs)
  File "src/netCDF4/_netCDF4.pyx", line 2463, in netCDF4._netCDF4.Dataset.__init__
  File "src/netCDF4/_netCDF4.pyx", line 2026, in netCDF4._netCDF4._ensure_nc_success
FileNotFoundError: [Errno 2] No such file or directory: b'/work_big/users/clima/portal/CRCM5-LE/psl/kbg/2066/psl_EUR-11_CCCma-CanESM2_rcp85_r1-r7i1p1_OURANOS-CRCM5_kbg_3h_206607.nc'
2025-09-23 18:20:55,845 - distributed.worker.state_machine - WARNING - Async instruction for <Task cancelled name="execute('compute_and_save_daily_mean-fabd0024-a51c-41fd-9a55-9715c78a0b3d')" coro=<Worker.execute() done, defined at /home/portal/anaconda3/envs/myenv/lib/python3.10/site-packages/distributed/worker_state_machine.py:3615>> ended with CancelledError
2025-09-23 18:20:55,846 - distributed.worker.state_machine - WARNING - Async instruction for <Task cancelled name="execute('compute_and_save_daily_mean-35f3e83c-cfb9-4078-aa7d-4fe414f5290f')" coro=<Worker.execute() done, defined at /home/portal/anaconda3/envs/myenv/lib/python3.10/site-packages/distributed/worker_state_machine.py:3615>> ended with CancelledError
2025-09-23 18:20:55,846 - distributed.worker.state_machine - WARNING - Async instruction for <Task cancelled name="execute('compute_and_save_daily_mean-cdc84fd7-7911-4a06-8b17-ffc9f758a051')" coro=<Worker.execute() done, defined at /home/portal/anaconda3/envs/myenv/lib/python3.10/site-packages/distributed/worker_state_machine.py:3615>> ended with CancelledError
2025-09-23 18:20:55,847 - distributed.worker.state_machine - WARNING - Async instruction for <Task cancelled name="execute('compute_and_save_daily_mean-f59736be-1786-4c0e-8150-67d0ba8dbf4e')" coro=<Worker.execute() done, defined at /home/portal/anaconda3/envs/myenv/lib/python3.10/site-packages/distributed/worker_state_machine.py:3615>> ended with CancelledError
2025-09-23 18:20:55,847 - distributed.worker.state_machine - WARNING - Async instruction for <Task cancelled name="execute('compute_and_save_daily_mean-2272afc3-4320-44aa-a4bf-de914e96f7df')" coro=<Worker.execute() done, defined at /home/portal/anaconda3/envs/myenv/lib/python3.10/site-packages/distributed/worker_state_machine.py:3615>> ended with CancelledError
2025-09-23 18:20:55,847 - distributed.worker.state_machine - WARNING - Async instruction for <Task cancelled name="execute('compute_and_save_daily_mean-a441f744-33e4-4a1b-ad54-70ef4dd241cc')" coro=<Worker.execute() done, defined at /home/portal/anaconda3/envs/myenv/lib/python3.10/site-packages/distributed/worker_state_machine.py:3615>> ended with CancelledError
2025-09-23 18:20:55,847 - distributed.worker.state_machine - WARNING - Async instruction for <Task cancelled name="execute('compute_and_save_daily_mean-beef11fc-cd32-4b3b-8eb9-30da98c1ebae')" coro=<Worker.execute() done, defined at /home/portal/anaconda3/envs/myenv/lib/python3.10/site-packages/distributed/worker_state_machine.py:3615>> ended with CancelledError
2025-09-23 18:20:55,848 - distributed.worker.state_machine - WARNING - Async instruction for <Task cancelled name="execute('compute_and_save_daily_mean-a153c30c-89f3-4268-8d2f-6cac094cf459')" coro=<Worker.execute() done, defined at /home/portal/anaconda3/envs/myenv/lib/python3.10/site-packages/distributed/worker_state_machine.py:3615>> ended with CancelledError

real	0m2.808s
user	0m5.571s
sys	0m11.051s
